{"uuid": "7f61830f-50d5-4ffc-baee-2aa0ea018c8b", "children": ["82b516ed-2e87-49ae-bdfe-29d662ff1db3", "5e5cd859-419d-409e-a9cd-05fbf98ce92c", "8ccd67dc-5d76-46e5-8f9b-0120425e8cd7", "6cc995d8-8a5f-4fe3-8456-d1eadd560808"], "befores": [{"name": "browser", "status": "broken", "statusDetails": {"message": "selenium.common.exceptions.WebDriverException: Message: 'chromedriver.exe' executable needs to be in PATH. Please see https://sites.google.com/a/chromium.org/chromedriver/home\n\n", "trace": "  File \"D:\\Python38\\lib\\site-packages\\pluggy\\callers.py\", line 187, in _multicall\n    res = hook_impl.function(*args)\n  File \"D:\\Python38\\lib\\site-packages\\_pytest\\fixtures.py\", line 964, in pytest_fixture_setup\n    result = call_fixture_func(fixturefunc, request, kwargs)\n  File \"D:\\Python38\\lib\\site-packages\\_pytest\\fixtures.py\", line 788, in call_fixture_func\n    res = next(it)\n  File \"C:\\Projects\\Ktp\\tests\\conftest.py\", line 17, in browser\n    driver = webdriver.Chrome(executable_path = r\"C:\\Users\\Administrator\\AppData\\Local\\Google\\Chrome\\Application\\chromedriver.exe\", options=chrome_options)\n  File \"D:\\Python38\\lib\\site-packages\\selenium\\webdriver\\chrome\\webdriver.py\", line 73, in __init__\n    self.service.start()\n  File \"D:\\Python38\\lib\\site-packages\\selenium\\webdriver\\common\\service.py\", line 81, in start\n    raise WebDriverException(\n"}, "start": 1594905798181, "stop": 1594905798185}], "start": 1594905798181, "stop": 1594905799200}