{"uuid": "f41ef130-abf0-4897-bba8-5f664e276c18", "children": ["bc701319-8bf6-4dfd-a9cc-540a6982f985"], "befores": [{"name": "browser", "status": "broken", "statusDetails": {"message": "selenium.common.exceptions.WebDriverException: Message: 'chromedriver.exe' executable needs to be in PATH. Please see https://sites.google.com/a/chromium.org/chromedriver/home\n\n", "trace": "  File \"D:\\Python38\\lib\\site-packages\\pluggy\\callers.py\", line 187, in _multicall\n    res = hook_impl.function(*args)\n  File \"D:\\Python38\\lib\\site-packages\\_pytest\\fixtures.py\", line 964, in pytest_fixture_setup\n    result = call_fixture_func(fixturefunc, request, kwargs)\n  File \"D:\\Python38\\lib\\site-packages\\_pytest\\fixtures.py\", line 788, in call_fixture_func\n    res = next(it)\n  File \"C:\\Projects\\Ktp\\tests\\conftest.py\", line 17, in browser\n    driver = webdriver.Chrome(executable_path = r\"C:\\Users\\Administrator\\AppData\\Local\\Google\\Chrome\\Application\\chromedriver.exe\", options=chrome_options)\n  File \"D:\\Python38\\lib\\site-packages\\selenium\\webdriver\\chrome\\webdriver.py\", line 73, in __init__\n    self.service.start()\n  File \"D:\\Python38\\lib\\site-packages\\selenium\\webdriver\\common\\service.py\", line 81, in start\n    raise WebDriverException(\n"}, "start": 1594905797144, "stop": 1594905797150}], "start": 1594905797144, "stop": 1594905798167}